Workbook

Sheet 商圈对比
A2: 八个商圈小户型10个月成本调整后回报率
A3: 仅精装/简装出售、整租；25–60㎡；先逐套计算，再对有效出售房源取中位数
A6: 商圈 | B6: 符合条件出售数 | C6: 匹配出售数 | D6: 匹配覆盖率 | E6: 出租房源数 | F6: 税费调整后回报率 | G6: 原10个月毛回报率
A7: 川音 | B7: 28 | C7: 17 | D7: =C7/B7 -> 0.60714286 | E7: 50 | F7: =(G7-税费参数!$B$12*SUM(税费参数!$B$9:税费参数!$B$10)/税费参数!$B$11)/(1+SUM(税费参数!$B$6:税费参数!$B$8)) -> 0.032774127 | G7: 0.035714286
A8: 棕北 | B8: 33 | C8: 29 | D8: =C8/B8 -> 0.87878788 | E8: 54 | F8: =(G8-税费参数!$B$12*SUM(税费参数!$B$9:税费参数!$B$10)/税费参数!$B$11)/(1+SUM(税费参数!$B$6:税费参数!$B$8)) -> 0.031436642 | G8: 0.034333333
A9: 西南财大 | B9: 36 | C9: 22 | D9: =C9/B9 -> 0.61111111 | E9: 85 | F9: =(G9-税费参数!$B$12*SUM(税费参数!$B$9:税费参数!$B$10)/税费参数!$B$11)/(1+SUM(税费参数!$B$6:税费参数!$B$8)) -> 0.030382841 | G9: 0.033245283
A10: 川大 | B10: 40 | C10: 34 | D10: =C10/B10 -> 0.85 | E10: 71 | F10: =(G10-税费参数!$B$12*SUM(税费参数!$B$9:税费参数!$B$10)/税费参数!$B$11)/(1+SUM(税费参数!$B$6:税费参数!$B$8)) -> 0.028208232 | G10: 0.031
A11: 华西 | B11: 28 | C11: 23 | D11: =C11/B11 -> 0.82142857 | E11: 73 | F11: =(G11-税费参数!$B$12*SUM(税费参数!$B$9:税费参数!$B$10)/税费参数!$B$11)/(1+SUM(税费参数!$B$6:税费参数!$B$8)) -> 0.028139052 | G11: 0.030928571
A12: 玉林 | B12: 11 | C12: 8 | D12: =C12/B12 -> 0.72727273 | E12: 29 | F12: =(G12-税费参数!$B$12*SUM(税费参数!$B$9:税费参数!$B$10)/税费参数!$B$11)/(1+SUM(税费参数!$B$6:税费参数!$B$8)) -> 0.024277974 | G12: 0.026942008
A13: 合江亭 | B13: 166 | C13: 124 | D13: =C13/B13 -> 0.74698795 | E13: 129 | F13: =(G13-税费参数!$B$12*SUM(税费参数!$B$9:税费参数!$B$10)/税费参数!$B$11)/(1+SUM(税费参数!$B$6:税费参数!$B$8)) -> 0.020981077 | G13: 0.023537962
A14: 盐市口 | B14: 197 | C14: 157 | D14: =C14/B14 -> 0.79695431 | E14: 201 | F14: =(G14-税费参数!$B$12*SUM(税费参数!$B$9:税费参数!$B$10)/税费参数!$B$11)/(1+SUM(税费参数!$B$6:税费参数!$B$8)) -> 0.015699861 | G14: 0.018085106
A16: 无可比出租房源的出售房源保留在“出售逐套”，回报率为空，不作为0%参与中位数。
A17: 每个出售房源的回报率＝该房源所有合格出租配对的回报率中位数；再汇总到户型、小区、商圈。
A18: 回报率已计买入3.25%及卖出2.25%/120个月摊销，可在“税费参数”调整；未扣物业费、修缮及出租税费。

Sheet 税费参数
A2: 投资回报率—可调整税费参数
A5: 项目 | B5: 参数值
A6: 买入契税 | B6: 0.01
A7: 买入个税 | B7: 0.01
A8: 买入中介费 | B8: 0.0125
A9: 卖出个税 | B9: 0.01
A10: 卖出中介费 | B10: 0.0125
A11: 卖出成本摊销月数 | B11: 120
A12: 年计租月数 | B12: 10
A14: 计算口径：年计租月数 ×（月租金 − 房价×(卖出个税＋卖出中介费)÷摊销月数）÷（房价×(1＋买入契税＋买入个税＋买入中介费)）
A15: 卖出税费按房价计提；每月扣除1/120，不是一次性扣除。所有价格均为挂牌价。
A16: 未计物业费、维修、额外税费、房屋空置损失及价格涨跌；10个月已体现简化空置假设。

Sheet 小区汇总
A2: 104个小区的成本调整后回报率
A3: 匹配不到租金的小区仍予保留；小区回报率为其有效出售房源回报率的中位数
A6: 商圈 | B6: 小区 | C6: 精简装出售数 | D6: 有租金匹配数 | E6: 覆盖率 | F6: 税费调整后回报率 | G6: 原毛回报率
A7: 华西 | B7: 艺墅花乡 | C7: 9 | D7: 7 | E7: =D7/C7 -> 0.77777778 | F7: =(G7-税费参数!$B$12*SUM(税费参数!$B$9:税费参数!$B$10)/税费参数!$B$11)/(1+SUM(税费参数!$B$6:税费参数!$B$8)) -> 0.033251232 | G7: 0.036206897
A8: 华西 | B8: 金茂礼都 | C8: 6 | D8: 6 | E8: =D8/C8 -> 1 | F8: =(G8-税费参数!$B$12*SUM(税费参数!$B$9:税费参数!$B$10)/税费参数!$B$11)/(1+SUM(税费参数!$B$6:税费参数!$B$8)) -> 0.030071635 | G8: 0.032923963
A9: 华西 | B9: 天乐嘉苑 | C9: 1 | D9: 1 | E9: =D9/C9 -> 1 | F9: =(G9-税费参数!$B$12*SUM(税费参数!$B$9:税费参数!$B$10)/税费参数!$B$11)/(1+SUM(税费参数!$B$6:税费参数!$B$8)) -> 0.029881136 | G9: 0.032727273
A10: 华西 | B10: 天竺丽苑 | C10: 2 | D10: 1 | E10: =D10/C10 -> 0.5 | F10: =(G10-税费参数!$B$12*SUM(税费参数!$B$9:税费参数!$B$10)/税费参数!$B$11)/(1+SUM(税费参数!$B$6:税费参数!$B$8)) -> 0.026594027 | G10: 0.029333333
A11: 华西 | B11: 黉门公馆 | C11: 3 | D11: 2 | E11: =D11/C11 -> 0.66666667 | F11: =(G11-税费参数!$B$12*SUM(税费参数!$B$9:税费参数!$B$10)/税费参数!$B$11)/(1+SUM(税费参数!$B$6:税费参数!$B$8)) -> 0.02610878 | G11: 0.028832315
A12: 华西 | B12: 凯蒂阳光 | C12: 2 | D12: 2 | E12: =D12/C12 -> 1 | F12: =(G12-税费参数!$B$12*SUM(税费参数!$B$9:税费参数!$B$10)/税费参数!$B$11)/(1+SUM(税费参数!$B$6:税费参数!$B$8)) -> 0.02573794 | G12: 0.028449423
A13: 华西 | B13: 城南世家 | C13: 1 | D13: 1 | E13: =D13/C13 -> 1 | F13: =(G13-税费参数!$B$12*SUM(税费参数!$B$9:税费参数!$B$10)/税费参数!$B$11)/(1+SUM(税费参数!$B$6:税费参数!$B$8)) -> 0.025453114 | G13: 0.02815534
A14: 华西 | B14: 傲仕门 | C14: 2 | D14: 2 | E14: =D14/C14 -> 1 | F14: =(G14-税费参数!$B$12*SUM(税费参数!$B$9:税费参数!$B$10)/税费参数!$B$11)/(1+SUM(税费参数!$B$6:税费参数!$B$8)) -> 0.023671467 | G14: 0.026315789
A15: 华西 | B15: 米兰风度花园 | C15: 5 | D15: 4 | E15: =D15/C15 -> 0.8 | F15: =(G15-税费参数!$B$12*SUM(税费参数!$B$9:税费参数!$B$10)/税费参数!$B$11)/(1+SUM(税费参数!$B$6:税费参数!$B$8)) -> 0.021503517 | G15: 0.024077381
A16: 华西 | B16: 通祠路14号 | C16: 1 | D16: 1 | E16: =D16/C16 -> 1 | F16: =(G16-税费参数!$B$12*SUM(税费参数!$B$9:税费参数!$B$10)/税费参数!$B$11)/(1+SUM(税费参数!$B$6:税费参数!$B$8)) -> 0.020914661 | G16: 0.023469388
A17: 华西 | B17: 丽景天成 | C17: 9 | D17: 4 | E17: =D17/C17 -> 0.44444444 | F17: =(G17-税费参数!$B$12*SUM(税费参数!$B$9:税费参数!$B$10)/税费参数!$B$11)/(1+SUM(税费参数!$B$6:税费参数!$B$8)) -> 0.019982595 | G17: 0.022507029
A18: 华西 | B18: 人民南路三段16号 | C18: 1 | D18: 0 | E18: =D18/C18 -> 0
A19: 华西 | B19: 铜锣湾 | C19: 1 | D19: 0 | E19: =D19/C19 -> 0
A20: 华西 | B20: 锦和名邸 | C20: 1 | D20: 0 | E20: =D20/C20 -> 0
A21: 合江亭 | B21: 龙瑞苑 | C21: 1 | D21: 1 | E21: =D21/C21 -> 1 | F21: =(G21-税费参数!$B$12*SUM(税费参数!$B$9:税费参数!$B$10)/税费参数!$B$11)/(1+SUM(税费参数!$B$6:税费参数!$B$8)) -> 0.027372384 | G21: 0.030136986
A22: 合江亭 | B22: 流星花园 | C22: 26 | D22: 25 | E22: =D22/C22 -> 0.96153846 | F22: =(G22-税费参数!$B$12*SUM(税费参数!$B$9:税费参数!$B$10)/税费参数!$B$11)/(1+SUM(税费参数!$B$6:税费参数!$B$8)) -> 0.025224662 | G22: 0.027919463
A23: 合江亭 | B23: SOHO我的寓所 | C23: 6 | D23: 4 | E23: =D23/C23 -> 0.66666667 | F23: =(G23-税费参数!$B$12*SUM(税费参数!$B$9:税费参数!$B$10)/税费参数!$B$11)/(1+SUM(税费参数!$B$6:税费参数!$B$8)) -> 0.024523499 | G23: 0.027195513
A24: 合江亭 | B24: 总府花园 | C24: 4 | D24: 3 | E24: =D24/C24 -> 0.75 | F24: =(G24-税费参数!$B$12*SUM(税费参数!$B$9:税费参数!$B$10)/税费参数!$B$11)/(1+SUM(税费参数!$B$6:税费参数!$B$8)) -> 0.022871861 | G24: 0.025490196
A25: 合江亭 | B25: 喜年广场 | C25: 27 | D25: 27 | E25: =D25/C25 -> 1 | F25: =(G25-税费参数!$B$12*SUM(税费参数!$B$9:税费参数!$B$10)/税费参数!$B$11)/(1+SUM(税费参数!$B$6:税费参数!$B$8)) -> 0.022166494 | G25: 0.024761905
A26: 合江亭 | B26: 蓉上坊一期 | C26: 13 | D26: 12 | E26: =D26/C26 -> 0.92307692 | F26: =(G26-税费参数!$B$12*SUM(税费参数!$B$9:税费参数!$B$10)/税费参数!$B$11)/(1+SUM(税费参数!$B$6:税费参数!$B$8)) -> 0.022109046 | G26: 0.02470259
A27: 合江亭 | B27: 上东吉座 | C27: 2 | D27: 1 | E27: =D27/C27 -> 0.5 | F27: =(G27-税费参数!$B$12*SUM(税费参数!$B$9:税费参数!$B$10)/税费参数!$B$11)/(1+SUM(税费参数!$B$6:税费参数!$B$8)) -> 0.02039785 | G27: 0.02293578
A28: 合江亭 | B28: 银唐国际 | C28: 1 | D28: 1 | E28: =D28/C28 -> 1 | F28: =(G28-税费参数!$B$12*SUM(税费参数!$B$9:税费参数!$B$10)/税费参数!$B$11)/(1+SUM(税费参数!$B$6:税费参数!$B$8)) -> 0.020158911 | G28: 0.022689076
A29: 合江亭 | B29: 锦上花 | C29: 17 | D29: 13 | E29: =D29/C29 -> 0.76470588 | F29: =(G29-税费参数!$B$12*SUM(税费参数!$B$9:税费参数!$B$10)/税费参数!$B$11)/(1+SUM(税费参数!$B$6:税费参数!$B$8)) -> 0.019765238 | G29: 0.022282609
A30: 合江亭 | B30: 光辉岁月 | C30: 4 | D30: 3 | E30: =D30/C30 -> 0.75 | F30: =(G30-税费参数!$B$12*SUM(税费参数!$B$9:税费参数!$B$10)/税费参数!$B$11)/(1+SUM(税费参数!$B$6:税费参数!$B$8)) -> 0.019535549 | G30: 0.022045455
A31: 合江亭 | B31: 星城银座 | C31: 17 | D31: 14 | E31: =D31/C31 -> 0.82352941 | F31: =(G31-税费参数!$B$12*SUM(税费参数!$B$9:税费参数!$B$10)/税费参数!$B$11)/(1+SUM(税费参数!$B$6:税费参数!$B$8)) -> 0.018794096 | G31: 0.021279904
A32: 合江亭 | B32: 蓝光郁金香花园广场 | C32: 10 | D32: 8 | E32: =D32/C32 -> 0.8 | F32: =(G32-税费参数!$B$12*SUM(税费参数!$B$9:税费参数!$B$10)/税费参数!$B$11)/(1+SUM(税费参数!$B$6:税费参数!$B$8)) -> 0.018681112 | G32: 0.021163249
... A35: 合江亭 | B35: 国际商务大厦 | C35: 7 | D35: 5 | E35: =D35/C35 -> 0.71428571 | F35: =(G35-税费参数!$B$12*SUM(税费参数!$B$9:税费参数!$B$10)/税费参数!$B$11)/(1+SUM(税费参数!$B$6:税费参数!$B$8)) -> 0.016990291 | G35: 0.019417476
A36: 合江亭 | B36: 三圣街21号 | C36: 1 | D36: 0 | E36: =D36/C36 -> 0
A37: 合江亭 | B37: 水岸银座 | C37: 1 | D37: 0 | E37: =D37/C37 -> 0
A38: 合江亭 | B38: 蓝光时代华章 | C38: 24 | D38: 0 | E38: =D38/C38 -> 0
A39: 川大 | B39: 好望角 | C39: 5 | D39: 5 | E39: =D39/C39 -> 1 | F39: =(G39-税费参数!$B$12*SUM(税费参数!$B$9:税费参数!$B$10)/税费参数!$B$11)/(1+SUM(税费参数!$B$6:税费参数!$B$8)) -> 0.039346247 | G39: 0.0425
A40: 川大 | B40: 蓝色加勒比广场 | C40: 1 | D40: 1 | E40: =D40/C40 -> 1 | F40: =(G40-税费参数!$B$12*SUM(税费参数!$B$9:税费参数!$B$10)/税费参数!$B$11)/(1+SUM(税费参数!$B$6:税费参数!$B$8)) -> 0.031544256 | G40: 0.034444444
A41: 川大 | B41: 樱花假日 | C41: 19 | D41: 16 | E41: =D41/C41 -> 0.84210526 | F41: =(G41-税费参数!$B$12*SUM(税费参数!$B$9:税费参数!$B$10)/税费参数!$B$11)/(1+SUM(税费参数!$B$6:税费参数!$B$8)) -> 0.029596494 | G41: 0.03243338
A42: 川大 | B42: 中海格林威治城小户 | C42: 3 | D42: 3 | E42: =D42/C42 -> 1 | F42: =(G42-税费参数!$B$12*SUM(税费参数!$B$9:税费参数!$B$10)/税费参数!$B$11)/(1+SUM(税费参数!$B$6:税费参数!$B$8)) -> 0.028833481 | G42: 0.03164557
A43: 川大 | B43: 棕榈花园 | C43: 3 | D43: 2 | E43: =D43/C43 -> 0.66666667 | F43: =(G43-税费参数!$B$12*SUM(税费参数!$B$9:税费参数!$B$10)/税费参数!$B$11)/(1+SUM(税费参数!$B$6:税费参数!$B$8)) -> 0.028357236 | G43: 0.031153846
A44: 川大 | B44: 和信派都 | C44: 12 | D44: 12 | E44: =D44/C44 -> 1 | F44: =(G44-税费参数!$B$12*SUM(税费参数!$B$9:税费参数!$B$10)/税费参数!$B$11)/(1+SUM(税费参数!$B$6:税费参数!$B$8)) -> 0.024624267 | G44: 0.027299556
A45: 川大 | B45: 纯真年代 | C45: 6 | D45: 5 | E45: =D45/C45 -> 0.83333333 | F45: =(G45-税费参数!$B$12*SUM(税费参数!$B$9:税费参数!$B$10)/税费参数!$B$11)/(1+SUM(税费参数!$B$6:税费参数!$B$8)) -> 0.022719935 | G45: 0.025333333
...

Sheet 户型汇总
A2: 各小区各面积户型成本调整后回报率
A3: 同商圈+小区+面积段+室厅数，出租面积相差≤15%；每套出售房源权重相同
A6: 商圈 | B6: 小区 | C6: 面积段 | D6: 室厅数 | E6: 出售数 | F6: 可匹配出售数 | G6: 匹配覆盖率 | H6: 出租候选数 | I6: 税费调整后回报率 | J6: 原毛回报率 | K6: 数据状态
A7: 华西 | B7: 丽景天成 | C7: 40–60㎡ | D7: 1室1厅 | E7: 2 | F7: 2 | G7: =F7/E7 -> 1 | H7: 2 | I7: =(J7-税费参数!$B$12*SUM(税费参数!$B$9:税费参数!$B$10)/税费参数!$B$11)/(1+SUM(税费参数!$B$6:税费参数!$B$8)) -> 0.020886241 | J7: 0.023440043 | K7: 可参考
A8: 华西 | B8: 丽景天成 | C8: 40–60㎡ | D8: 2室1厅 | E8: 2 | F8: 0 | G8: =F8/E8 -> 0 | H8: 0 | K8: 无匹配
A9: 华西 | B9: 丽景天成 | C9: 60–90㎡ | D9: 1室1厅 | E9: 2 | F9: 2 | G9: =F9/E9 -> 1 | H9: 1 | I9: =(J9-税费参数!$B$12*SUM(税费参数!$B$9:税费参数!$B$10)/税费参数!$B$11)/(1+SUM(税费参数!$B$6:税费参数!$B$8)) -> 0.018434955 | J9: 0.020909091 | K9: 低样本
A10: 华西 | B10: 丽景天成 | C10: 60–90㎡ | D10: 2室1厅 | E10: 3 | F10: 0 | G10: =F10/E10 -> 0 | H10: 0 | K10: 无匹配
A11: 华西 | B11: 人民南路三段16号 | C11: 60–90㎡ | D11: 2室1厅 | E11: 1 | F11: 0 | G11: =F11/E11 -> 0 | H11: 0 | K11: 无匹配
A12: 华西 | B12: 傲仕门 | C12: 40–60㎡ | D12: 1室1厅 | E12: 2 | F12: 2 | G12: =F12/E12 -> 1 | H12: 2 | I12: =(J12-税费参数!$B$12*SUM(税费参数!$B$9:税费参数!$B$10)/税费参数!$B$11)/(1+SUM(税费参数!$B$6:税费参数!$B$8)) -> 0.023671467 | J12: 0.026315789 | K12: 可参考
A13: 华西 | B13: 凯蒂阳光 | C13: 40–60㎡ | D13: 1室1厅 | E13: 2 | F13: 2 | G13: =F13/E13 -> 1 | H13: 2 | I13: =(J13-税费参数!$B$12*SUM(税费参数!$B$9:税费参数!$B$10)/税费参数!$B$11)/(1+SUM(税费参数!$B$6:税费参数!$B$8)) -> 0.02573794 | J13: 0.028449423 | K13: 可参考
A14: 华西 | B14: 城南世家 | C14: 60–90㎡ | D14: 2室1厅 | E14: 1 | F14: 1 | G14: =F14/E14 -> 1 | H14: 1 | I14: =(J14-税费参数!$B$12*SUM(税费参数!$B$9:税费参数!$B$10)/税费参数!$B$11)/(1+SUM(税费参数!$B$6:税费参数!$B$8)) -> 0.025453114 | J14: 0.02815534 | K14: 低样本
A15: 华西 | B15: 天乐嘉苑 | C15: 40–60㎡ | D15: 1室1厅 | E15: 1 | F15: 1 | G15: =F15/E15 -> 1 | H15: 1 | I15: =(J15-税费参数!$B$12*SUM(税费参数!$B$9:税费参数!$B$10)/税费参数!$B$11)/(1+SUM(税费参数!$B$6:税费参数!$B$8)) -> 0.029881136 | J15: 0.032727273 | K15: 低样本
A16: 华西 | B16: 天竺丽苑 | C16: 40–60㎡ | D16: 1室1厅 | E16: 1 | F16: 1 | G16: =F16/E16 -> 1 | H16: 1 | I16: =(J16-税费参数!$B$12*SUM(税费参数!$B$9:税费参数!$B$10)/税费参数!$B$11)/(1+SUM(税费参数!$B$6:税费参数!$B$8)) -> 0.026594027 | J16: 0.029333333 | K16: 低样本
A17: 华西 | B17: 天竺丽苑 | C17: 60–90㎡ | D17: 2室1厅 | E17: 1 | F17: 0 | G17: =F17/E17 -> 0 | H17: 1 | K17: 无匹配
A18: 华西 | B18: 米兰风度花园 | C18: 40–60㎡ | D18: 1室1厅 | E18: 1 | F18: 1 | G18: =F18/E18 -> 1 | H18: 2 | I18: =(J18-税费参数!$B$12*SUM(税费参数!$B$9:税费参数!$B$10)/税费参数!$B$11)/(1+SUM(税费参数!$B$6:税费参数!$B$8)) -> 0.02604564 | J18: 0.028767123 | K18: 低样本
A19: 华西 | B19: 米兰风度花园 | C19: 40–60㎡ | D19: 2室1厅 | E19: 1 | F19: 1 | G19: =F19/E19 -> 1 | H19: 1 | I19: =(J19-税费参数!$B$12*SUM(税费参数!$B$9:税费参数!$B$10)/税费参数!$B$11)/(1+SUM(税费参数!$B$6:税费参数!$B$8)) -> 0.023607748 | J19: 0.02625 | K19: 低样本
A20: 华西 | B20: 米兰风度花园 | C20: 60–90㎡ | D20: 2室1厅 | E20: 2 | F20: 2 | G20: =F20/E20 -> 1 | H20: 2 | I20: =(J20-税费参数!$B$12*SUM(税费参数!$B$9:税费参数!$B$10)/税费参数!$B$11)/(1+SUM(税费参数!$B$6:税费参数!$B$8)) -> 0.019399285 | J20: 0.021904762 | K20: 可参考
A21: 华西 | B21: 米兰风度花园 | C21: ≤40㎡ | D21: 1室1厅 | E21: 1 | F21: 0 | G21: =F21/E21 -> 0 | H21: 0 | K21: 无匹配
A22: 华西 | B22: 艺墅花乡 | C22: 40–60㎡ | D22: 1室0厅 | E22: 5 | F22: 5 | G22: =F22/E22 -> 1 | H22: 1 | I22: =(J22-税费参数!$B$12*SUM(税费参数!$B$9:税费参数!$B$10)/税费参数!$B$11)/(1+SUM(税费参数!$B$6:税费参数!$B$8)) -> 0.033251232 | J22: 0.036206897 | K22: 低样本
A23: 华西 | B23: 艺墅花乡 | C23: 40–60㎡ | D23: 1室1厅 | E23: 1 | F23: 0 | G23: =F23/E23 -> 0 | H23: 0 | K23: 无匹配
A24: 华西 | B24: 艺墅花乡 | C24: 40–60㎡ | D24: 2室1厅 | E24: 2 | F24: 2 | G24: =F24/E24 -> 1 | H24: 1 | I24: =(J24-税费参数!$B$12*SUM(税费参数!$B$9:税费参数!$B$10)/税费参数!$B$11)/(1+SUM(税费参数!$B$6:税费参数!$B$8)) -> 0.054565894 | J24: 0.058214286 | K24: 低样本
A25: 华西 | B25: 艺墅花乡 | C25: ≤40㎡ | D25: 1室1厅 | E25: 1 | F25: 0 | G25: =F25/E25 -> 0 | H25: 0 | K25: 无匹配
A26: 华西 | B26: 通祠路14号 | C26: 60–90㎡ | D26: 2室1厅 | E26: 1 | F26: 1 | G26: =F26/E26 -> 1 | H26: 1 | I26: =(J26-税费参数!$B$12*SUM(税费参数!$B$9:税费参数!$B$10)/税费参数!$B$11)/(1+SUM(税费参数!$B$6:税费参数!$B$8)) -> 0.020914661 | J26: 0.023469388 | K26: 低样本
A27: 华西 | B27: 金茂礼都 | C27: 40–60㎡ | D27: 1室1厅 | E27: 3 | F27: 3 | G27: =F27/E27 -> 1 | H27: 16 | I27: =(J27-税费参数!$B$12*SUM(税费参数!$B$9:税费参数!$B$10)/税费参数!$B$11)/(1+SUM(税费参数!$B$6:税费参数!$B$8)) -> 0.032004218 | J27: 0.034919355 | K27: 可参考
A28: 华西 | B28: 金茂礼都 | C28: 60–90㎡ | D28: 2室1厅 | E28: 2 | F28: 2 | G28: =F28/E28 -> 1 | H28: 3 | I28: =(J28-税费参数!$B$12*SUM(税费参数!$B$9:税费参数!$B$10)/税费参数!$B$11)/(1+SUM(税费参数!$B$6:税费参数!$B$8)) -> 0.026253838 | J28: 0.028982088 | K28: 可参考
A29: 华西 | B29: 金茂礼都 | C29: ≤40㎡ | D29: 1室1厅 | E29: 1 | F29: 1 | G29: =F29/E29 -> 1 | H29: 2 | I29: =(J29-税费参数!$B$12*SUM(税费参数!$B$9:税费参数!$B$10)/税费参数!$B$11)/(1+SUM(税费参数!$B$6:税费参数!$B$8)) -> 0.051012547 | J29: 0.054545455 | K29: 低样本
A30: 华西 | B30: 铜锣湾 | C30: 60–90㎡ | D30: 1室1厅 | E30: 1 | F30: 0 | G30: =F30/E30 -> 0 | H30: 0 | K30: 无匹配
A31: 华西 | B31: 锦和名邸 | C31: 60–90㎡ | D31: 2室1厅 | E31: 1 | F31: 0 | G31: =F31/E31 -> 0 | H31: 0 | K31: 无匹配
A32: 华西 | B32: 黉门公馆 | C32: 40–60㎡ | D32: 1室1厅 | E32: 2 | F32: 2 | G32: =F32/E32 -> 1 | H32: 8 | I32: =(J32-税费参数!$B$12*SUM(税费参数!$B$9:税费参数!$B$10)/税费参数!$B$11)/(1+SUM(税费参数!$B$6:税费参数!$B$8)) -> 0.02610878 | J32: 0.028832315 | K32: 可参考
A33: 华西 | B33: 黉门公馆 | C33: 60–90㎡ | D33: 1室1厅 | E33: 1 | F33: 0 | G33: =F33/E33 -> 0 | H33: 0 | K33: 无匹配
A34: 合江亭 | B34: SOHO我的寓所 | C34: 40–60㎡ | D34: 1室1厅 | E34: 2 | F34: 2 | G34: =F34/E34 -> 1 | H34: 2 | I34: =(J34-税费参数!$B$12*SUM(税费参数!$B$9:税费参数!$B$10)/税费参数!$B$11)/(1+SUM(税费参数!$B$6:税费参数!$B$8)) -> 0.026957224 | J34: 0.029708333 | K34: 可参考
A35: 合江亭 | B35: SOHO我的寓所 | C35: 40–60㎡ | D35: 2室1厅 | E35: 1 | F35: 0 | G35: =F35/E35 -> 0 | H35: 0 | K35: 无匹配
A36: 合江亭 | B36: SOHO我的寓所 | C36: ≤40㎡ | D36: 1室1厅 | E36: 3 | F36: 2 | G36: =F36/E36 -> 0.66666667 | H36: 2 | I36: =(J36-税费参数!$B$12*SUM(税费参数!$B$9:税费参数!$B$10)/税费参数!$B$11)/(1+SUM(税费参数!$B$6:税费参数!$B$8)) -> 0.022558055 | J36: 0.025166192 | K36: 可参考
A37: 合江亭 | B37: 三圣街21号 | C37: 60–90㎡ | D37: 2室1厅 | E37: 1 | F37: 0 | G37: =F37/E37 -> 0 | H37: 0 | K37: 无匹配
A38: 合江亭 | B38: 上东吉座 | C38: 40–60㎡ | D38: 1室1厅 | E38: 2 | F38: 1 | G38: =F38/E38 -> 0.5 | H38: 2 | I38: =(J38-税费参数!$B$12*SUM(税费参数!$B$9:税费参数!$B$10)/税费参数!$B$11)/(1+SUM(税费参数!$B$6:税费参数!$B$8)) -> 0.02039785 | J38: 0.02293578 | K38: 低样本
A39: 合江亭 | B39: 光辉岁月 | C39: 60–90㎡ | D39: 1室1厅 | E39: 3 | F39: 3 | G39: =F39/E39 -> 1 | H39: 1 | I39: =(J39-税费参数!$B$12*SUM(税费参数!$B$9:税费参数!$B$10)/税费参数!$B$11)/(1+SUM(税费参数!$B$6:税费参数!$B$8)) -> 0.019535549 | J39: 0.022045455 | K39: 低样本
A40: 合江亭 | B40: 光辉岁月 | C40: 60–90㎡ | D40: 2室1厅 | E40: 1 | F40: 0 | G40: =F40/E40 -> 0 | H40: 0 | K40: 无匹配
A41: 合江亭 | B41: 喜年广场 | C41: 40–60㎡ | D41: 1室0厅 | E41: 15 | F41: 15 | G41: =F41/E41 -> 1 | H41: 6 | I41: =(J41-税费参数!$B$12*SUM(税费参数!$B$9:税费参数!$B$10)/税费参数!$B$11)/(1+SUM(税费参数!$B$6:税费参数!$B$8)) -> 0.022166494 | J41: 0.024761905 | K41: 可参考
A42: 合江亭 | B42: 喜年广场 | C42: 40–60㎡ | D42: 1室1厅 | E42: 12 | F42: 12 | G42: =F42/E42 -> 1 | H42: 4 | I42: =(J42-税费参数!$B$12*SUM(税费参数!$B$9:税费参数!$B$10)/税费参数!$B$11)/(1+SUM(税费参数!$B$6:税费参数!$B$8)) -> 0.022281794 | J42: 0.024880952 | K42: 可参考
A43: 合江亭 | B43: 国际商务大厦 | C43: 40–60㎡ | D43: 1室0厅 | E43: 1 | F43: 1 | G43: =F43/E43 -> 1 | H43: 4 | I43: =(J43-税费参数!$B$12*SUM(税费参数!$B$9:税费参数!$B$10)/税费参数!$B$11)/(1+SUM(税费参数!$B$6:税费参数!$B$8)) -> 0.015793529 | J43: 0.018181818 | K43: 低样本
...

Sheet 出售逐套
A2: 全部701套精装或简装出售房源
A3: 逐套成本调整后回报率取所有出租配对的中位数；无法匹配时留空
A6: 商圈 | B6: 小区 | C6: 面积段 | D6: 房型 | E6: 房源编号 | F6: 装修 | G6: 面积㎡ | H6: 售价万 | I6: 匹配出租数 | J6: 调整后回报率 | K6: 链接 | L6: 原毛回报率
A7: 华西 | B7: 丽景天成 | C7: 40–60㎡ | D7: 1室1厅 | E7: 106129412042.0 | F7: 精装 | G7: 57.93 | H7: 95 | I7: 2 | J7: =MEDIAN(租金配对!K9:K10) -> 0.021122722 | K7: https://cd.lianjia.com/ershoufang/106129412042.html | L7: =MEDIAN(租金配对!L9:L10) -> 0.023684211
A8: 华西 | B8: 丽景天成 | C8: 40–60㎡ | D8: 1室1厅 | E8: 106129483566.0 | F8: 简装 | G8: 59.3 | H8: 97 | I8: 2 | J8: =MEDIAN(租金配对!K7:K8) -> 0.020649759 | K8: https://cd.lianjia.com/ershoufang/106129483566.html | L8: =MEDIAN(租金配对!L7:L8) -> 0.023195876
A9: 华西 | B9: 丽景天成 | C9: 40–60㎡ | D9: 2室1厅 | E9: 106118664527.0 | F9: 精装 | G9: 56.34 | H9: 102 | I9: 0 | K9: https://cd.lianjia.com/ershoufang/106118664527.html
A10: 华西 | B10: 丽景天成 | C10: 40–60㎡ | D10: 2室1厅 | E10: 106127557823.0 | F10: 精装 | G10: 58.52 | H10: 117 | I10: 0 | K10: https://cd.lianjia.com/ershoufang/106127557823.html
A11: 华西 | B11: 丽景天成 | C11: 60–90㎡ | D11: 1室1厅 | E11: 106114386047.0 | F11: 简装 | G11: 60.74 | H11: 120 | I11: 1 | J11: =MEDIAN(租金配对!K12:K12) -> 0.017554479 | K11: https://cd.lianjia.com/ershoufang/106114386047.html | L11: =MEDIAN(租金配对!L12:L12) -> 0.02
A12: 华西 | B12: 丽景天成 | C12: 60–90㎡ | D12: 1室1厅 | E12: 106117140666.0 | F12: 精装 | G12: 60.74 | H12: 110 | I12: 1 | J12: =MEDIAN(租金配对!K11:K11) -> 0.01931543 | K12: https://cd.lianjia.com/ershoufang/106117140666.html | L12: =MEDIAN(租金配对!L11:L11) -> 0.021818182
A13: 华西 | B13: 丽景天成 | C13: 60–90㎡ | D13: 2室1厅 | E13: 106123825538.0 | F13: 精装 | G13: 60.4 | H13: 108 | I13: 0 | K13: https://cd.lianjia.com/ershoufang/106123825538.html
A14: 华西 | B14: 丽景天成 | C14: 60–90㎡ | D14: 2室1厅 | E14: 106128883747.0 | F14: 简装 | G14: 75.8 | H14: 112 | I14: 0 | K14: https://cd.lianjia.com/ershoufang/106128883747.html
A15: 华西 | B15: 丽景天成 | C15: 60–90㎡ | D15: 2室1厅 | E15: 106128956197.0 | F15: 简装 | G15: 75.8 | H15: 108 | I15: 0 | K15: https://cd.lianjia.com/ershoufang/106128956197.html
A16: 华西 | B16: 人民南路三段16号 | C16: 60–90㎡ | D16: 2室1厅 | E16: 106127607383.0 | F16: 简装 | G16: 77 | H16: 110 | I16: 0 | K16: https://cd.lianjia.com/ershoufang/106127607383.html
A17: 华西 | B17: 傲仕门 | C17: 40–60㎡ | D17: 1室1厅 | E17: 106121807884.0 | F17: 精装 | G17: 55.41 | H17: 95 | I17: 2 | J17: =MEDIAN(租金配对!K13:K14) -> 0.023671467 | K17: https://cd.lianjia.com/ershoufang/106121807884.html | L17: =MEDIAN(租金配对!L13:L14) -> 0.026315789
A18: 华西 | B18: 傲仕门 | C18: 40–60㎡ | D18: 1室1厅 | E18: 106123379786.0 | F18: 精装 | G18: 59.44 | H18: 95 | I18: 2 | J18: =MEDIAN(租金配对!K15:K16) -> 0.023671467 | K18: https://cd.lianjia.com/ershoufang/106123379786.html | L18: =MEDIAN(租金配对!L15:L16) -> 0.026315789
A19: 华西 | B19: 凯蒂阳光 | C19: 40–60㎡ | D19: 1室1厅 | E19: 106123405462.0 | F19: 简装 | G19: 51.94 | H19: 98 | I19: 2 | J19: =MEDIAN(租金配对!K17:K18) -> 0.024867816 | K19: https://cd.lianjia.com/ershoufang/106123405462.html | L19: =MEDIAN(租金配对!L17:L18) -> 0.02755102
A20: 华西 | B20: 凯蒂阳光 | C20: 40–60㎡ | D20: 1室1厅 | E20: 106127993289.0 | F20: 简装 | G20: 48.56 | H20: 92 | I20: 2 | J20: =MEDIAN(租金配对!K19:K20) -> 0.026608064 | K20: https://cd.lianjia.com/ershoufang/106127993289.html | L20: =MEDIAN(租金配对!L19:L20) -> 0.029347826
A21: 华西 | B21: 城南世家 | C21: 60–90㎡ | D21: 2室1厅 | E21: 106129068792.0 | F21: 简装 | G21: 68.61 | H21: 103 | I21: 1 | J21: =MEDIAN(租金配对!K21:K21) -> 0.025453114 | K21: https://cd.lianjia.com/ershoufang/106129068792.html | L21: =MEDIAN(租金配对!L21:L21) -> 0.02815534
A22: 华西 | B22: 天乐嘉苑 | C22: 40–60㎡ | D22: 1室1厅 | E22: 106127114539.0 | F22: 简装 | G22: 44.29 | H22: 55 | I22: 1 | J22: =MEDIAN(租金配对!K22:K22) -> 0.029881136 | K22: https://cd.lianjia.com/ershoufang/106127114539.html | L22: =MEDIAN(租金配对!L22:L22) -> 0.032727273
A23: 华西 | B23: 天竺丽苑 | C23: 40–60㎡ | D23: 1室1厅 | E23: 106129150378.0 | F23: 简装 | G23: 47.04 | H23: 75 | I23: 1 | J23: =MEDIAN(租金配对!K23:K23) -> 0.026594027 | K23: https://cd.lianjia.com/ershoufang/106129150378.html | L23: =MEDIAN(租金配对!L23:L23) -> 0.029333333
A24: 华西 | B24: 天竺丽苑 | C24: 60–90㎡ | D24: 2室1厅 | E24: 106129574000.0 | F24: 精装 | G24: 61.5 | H24: 91 | I24: 0 | K24: https://cd.lianjia.com/ershoufang/106129574000.html
A25: 华西 | B25: 米兰风度花园 | C25: 40–60㎡ | D25: 1室1厅 | E25: 106124158582.0 | F25: 简装 | G25: 52.51 | H25: 73 | I25: 2 | J25: =MEDIAN(租金配对!K24:K25) -> 0.02604564 | K25: https://cd.lianjia.com/ershoufang/106124158582.html | L25: =MEDIAN(租金配对!L24:L25) -> 0.028767123
A26: 华西 | B26: 米兰风度花园 | C26: 40–60㎡ | D26: 2室1厅 | E26: 106127339364.0 | F26: 精装 | G26: 52.51 | H26: 80 | I26: 1 | J26: =MEDIAN(租金配对!K26:K26) -> 0.023607748 | K26: https://cd.lianjia.com/ershoufang/106127339364.html | L26: =MEDIAN(租金配对!L26:L26) -> 0.02625
A27: 华西 | B27: 米兰风度花园 | C27: 60–90㎡ | D27: 2室1厅 | E27: 106127189136.0 | F27: 精装 | G27: 69.69 | H27: 105 | I27: 2 | J27: =MEDIAN(租金配对!K29:K30) -> 0.019399285 | K27: https://cd.lianjia.com/ershoufang/106127189136.html | L27: =MEDIAN(租金配对!L29:L30) -> 0.021904762
A28: 华西 | B28: 米兰风度花园 | C28: 60–90㎡ | D28: 2室1厅 | E28: 106128046504.0 | F28: 简装 | G28: 69.88 | H28: 105 | I28: 2 | J28: =MEDIAN(租金配对!K27:K28) -> 0.019399285 | K28: https://cd.lianjia.com/ershoufang/106128046504.html | L28: =MEDIAN(租金配对!L27:L28) -> 0.021904762
A29: 华西 | B29: 米兰风度花园 | C29: ≤40㎡ | D29: 1室1厅 | E29: 106115572764.0 | F29: 简装 | G29: 37.07 | H29: 75 | I29: 0 | K29: https://cd.lianjia.com/ershoufang/106115572764.html
A30: 华西 | B30: 艺墅花乡 | C30: 40–60㎡ | D30: 1室0厅 | E30: 106115608951.0 | F30: 精装 | G30: 41.74 | H30: 50 | I30: 1 | J30: =MEDIAN(租金配对!K33:K33) -> 0.038861985 | K30: https://cd.lianjia.com/ershoufang/106115608951.html | L30: =MEDIAN(租金配对!L33:L33) -> 0.042
A31: 华西 | B31: 艺墅花乡 | C31: 40–60㎡ | D31: 1室0厅 | E31: 106124681209.0 | F31: 简装 | G31: 48.01 | H31: 59.8 | I31: 1 | J31: =MEDIAN(租金配对!K32:K32) -> 0.032195697 | K31: https://cd.lianjia.com/ershoufang/106124681209.html | L31: =MEDIAN(租金配对!L32:L32) -> 0.035117057
A32: 华西 | B32: 艺墅花乡 | C32: 40–60㎡ | D32: 1室0厅 | E32: 106124773262.0 | F32: 简装 | G32: 47.97 | H32: 58 | I32: 1 | J32: =MEDIAN(租金配对!K35:K35) -> 0.033251232 | K32: https://cd.lianjia.com/ershoufang/106124773262.html | L32: =MEDIAN(租金配对!L35:L35) -> 0.036206897
A33: 华西 | B33: 艺墅花乡 | C33: 40–60㎡ | D33: 1室0厅 | E33: 106124773286.0 | F33: 简装 | G33: 47.97 | H33: 63 | I33: 1 | J33: =MEDIAN(租金配对!K34:K34) -> 0.030468119 | K33: https://cd.lianjia.com/ershoufang/106124773286.html | L33: =MEDIAN(租金配对!L34:L34) -> 0.033333333
A34: 华西 | B34: 艺墅花乡 | C34: 40–60㎡ | D34: 1室0厅 | E34: 106126498573.0 | F34: 简装 | G34: 47.97 | H34: 58 | I34: 1 | J34: =MEDIAN(租金配对!K31:K31) -> 0.033251232 | K34: https://cd.lianjia.com/ershoufang/106126498573.html | L34: =MEDIAN(租金配对!L31:L31) -> 0.036206897
A35: 华西 | B35: 艺墅花乡 | C35: 40–60㎡ | D35: 1室1厅 | E35: 106123148784.0 | F35: 精装 | G35: 44.72 | H35: 77.8 | I35: 0 | K35: https://cd.lianjia.com/ershoufang/106123148784.html
A36: 华西 | B36: 艺墅花乡 | C36: 40–60㎡ | D36: 2室1厅 | E36: 106116981602.0 | F36: 简装 | G36: 42.17 | H36: 63 | I36: 1 | J36: =MEDIAN(租金配对!K37:K37) -> 0.067364234 | K36: https://cd.lianjia.com/ershoufang/106116981602.html | L36: =MEDIAN(租金配对!L37:L37) -> 0.071428571
A37: 华西 | B37: 艺墅花乡 | C37: 40–60㎡ | D37: 2室1厅 | E37: 106118801081.0 | F37: 简装 | G37: 53.95 | H37: 100 | I37: 1 | J37: =MEDIAN(租金配对!K36:K36) -> 0.041767554 | K37: https://cd.lianjia.com/ershoufang/106118801081.html | L37: =MEDIAN(租金配对!L36:L36) -> 0.045
A38: 华西 | B38: 艺墅花乡 | C38: ≤40㎡ | D38: 1室1厅 | E38: 106128828442.0 | F38: 简装 | G38: 35.66 | H38: 68 | I38: 0 | K38: https://cd.lianjia.com/ershoufang/106128828442.html
A39: 华西 | B39: 通祠路14号 | C39: 60–90㎡ | D39: 2室1厅 | E39: 106128171374.0 | F39: 简装 | G39: 82.74 | H39: 98 | I39: 1 | J39: =MEDIAN(租金配对!K38:K38) -> 0.020914661 | K39: https://cd.lianjia.com/ershoufang/106128171374.html | L39: =MEDIAN(租金配对!L38:L38) -> 0.023469388
A40: 华西 | B40: 金茂礼都 | C40: 40–60㎡ | D40: 1室1厅 | E40: 106120376840.0 | F40: 简装 | G40: 44.51 | H40: 61 | I40: 16 | J40: =MEDIAN(租金配对!K41:K56) -> 0.032558647 | K40: https://cd.lianjia.com/ershoufang/106120376840.html | L40: =MEDIAN(租金配对!L41:L56) -> 0.035491803
A41: 华西 | B41: 金茂礼都 | C41: 40–60㎡ | D41: 1室1厅 | E41: 106129590974.0 | F41: 精装 | G41: 44.14 | H41: 62 | I41: 16 | J41: =MEDIAN(租金配对!K73:K88) -> 0.032004218 | K41: https://cd.lianjia.com/ershoufang/106129590974.html | L41: =MEDIAN(租金配对!L73:L88) -> 0.034919355
A42: 华西 | B42: 金茂礼都 | C42: 40–60㎡ | D42: 1室1厅 | E42: 106129626353.0 | F42: 简装 | G42: 48.73 | H42: 70 | I42: 16 | J42: =MEDIAN(租金配对!K57:K72) -> 0.028139052 | K42: https://cd.lianjia.com/ershoufang/106129626353.html | L42: =MEDIAN(租金配对!L57:L72) -> 0.030928571
A43: 华西 | B43: 金茂礼都 | C43: 60–90㎡ | D43: 2室1厅 | E43: 106123772639.0 | F43: 精装 | G43: 63.43 | H43: 109 | I43: 2 | J43: =MEDIAN(租金配对!K91:K92) -> 0.025729169 | K43: https://cd.lianjia.com/ershoufang/106123772639.html | L43: =MEDIAN(租金配对!L91:L92) -> 0.028440367
...

Sheet 租金配对
A2: 2587个出售-出租配对
A3: 逐对扣买入成本及卖出摊销；各出售房源的多个配对仅用于求其自身中位数
A6: 商圈 | B6: 小区 | C6: 面积段 | D6: 房型 | E6: 出售编号 | F6: 出租编号 | G6: 出售面积㎡ | H6: 出租面积㎡ | I6: 售价万 | J6: 租金元/月 | K6: 调整后回报率 | L6: 原毛回报率 | M6: 卖出月摊销元
A7: 华西 | B7: 丽景天成 | C7: 40–60㎡ | D7: 1室1厅 | E7: 106129483566.0 | F7: CD2190079646437998592 | G7: 59.3 | H7: 57.93 | I7: 97 | J7: 2200 | K7: =(J7-M7)*税费参数!$B$12/(I7*10000*(1+SUM(税费参数!$B$6:$B$8))) -> 0.02015052 | L7: =J7*税费参数!$B$12/(I7*10000) -> 0.022680412 | M7: =I7*10000*SUM(税费参数!$B$9:$B$10)/税费参数!$B$11 -> 181.875
A8: 华西 | B8: 丽景天成 | C8: 40–60㎡ | D8: 1室1厅 | E8: 106129483566.0 | F8: CD2202410575210741760 | G8: 59.3 | H8: 60 | I8: 97 | J8: 2300 | K8: =(J8-M8)*税费参数!$B$12/(I8*10000*(1+SUM(税费参数!$B$6:$B$8))) -> 0.021148998 | L8: =J8*税费参数!$B$12/(I8*10000) -> 0.02371134 | M8: =I8*10000*SUM(税费参数!$B$9:$B$10)/税费参数!$B$11 -> 181.875
A9: 华西 | B9: 丽景天成 | C9: 40–60㎡ | D9: 1室1厅 | E9: 106129412042.0 | F9: CD2190079646437998592 | G9: 57.93 | H9: 57.93 | I9: 95 | J9: 2200 | K9: =(J9-M9)*税费参数!$B$12/(I9*10000*(1+SUM(税费参数!$B$6:$B$8))) -> 0.020612973 | L9: =J9*税费参数!$B$12/(I9*10000) -> 0.023157895 | M9: =I9*10000*SUM(税费参数!$B$9:$B$10)/税费参数!$B$11 -> 178.125
A10: 华西 | B10: 丽景天成 | C10: 40–60㎡ | D10: 1室1厅 | E10: 106129412042.0 | F10: CD2202410575210741760 | G10: 57.93 | H10: 60 | I10: 95 | J10: 2300 | K10: =(J10-M10)*税费参数!$B$12/(I10*10000*(1+SUM(税费参数!$B$6:$B$8))) -> 0.021632471 | L10: =J10*税费参数!$B$12/(I10*10000) -> 0.024210526 | M10: =I10*10000*SUM(税费参数!$B$9:$B$10)/税费参数!$B$11 -> 178.125
A11: 华西 | B11: 丽景天成 | C11: 60–90㎡ | D11: 1室1厅 | E11: 106117140666.0 | F11: CD2195559948966952960 | G11: 60.74 | H11: 62.16 | I11: 110 | J11: 2400 | K11: =(J11-M11)*税费参数!$B$12/(I11*10000*(1+SUM(税费参数!$B$6:$B$8))) -> 0.01931543 | L11: =J11*税费参数!$B$12/(I11*10000) -> 0.021818182 | M11: =I11*10000*SUM(税费参数!$B$9:$B$10)/税费参数!$B$11 -> 206.25
A12: 华西 | B12: 丽景天成 | C12: 60–90㎡ | D12: 1室1厅 | E12: 106114386047.0 | F12: CD2195559948966952960 | G12: 60.74 | H12: 62.16 | I12: 120 | J12: 2400 | K12: =(J12-M12)*税费参数!$B$12/(I12*10000*(1+SUM(税费参数!$B$6:$B$8))) -> 0.017554479 | L12: =J12*税费参数!$B$12/(I12*10000) -> 0.02 | M12: =I12*10000*SUM(税费参数!$B$9:$B$10)/税费参数!$B$11 -> 225
A13: 华西 | B13: 傲仕门 | C13: 40–60㎡ | D13: 1室1厅 | E13: 106121807884.0 | F13: CD2201683724582518784 | G13: 55.41 | H13: 59.44 | I13: 95 | J13: 2700 | K13: =(J13-M13)*税费参数!$B$12/(I13*10000*(1+SUM(税费参数!$B$6:$B$8))) -> 0.025710463 | L13: =J13*税费参数!$B$12/(I13*10000) -> 0.028421053 | M13: =I13*10000*SUM(税费参数!$B$9:$B$10)/税费参数!$B$11 -> 178.125
A14: 华西 | B14: 傲仕门 | C14: 40–60㎡ | D14: 1室1厅 | E14: 106121807884.0 | F14: CD2214344428011651072 | G14: 55.41 | H14: 57.05 | I14: 95 | J14: 2300 | K14: =(J14-M14)*税费参数!$B$12/(I14*10000*(1+SUM(税费参数!$B$6:$B$8))) -> 0.021632471 | L14: =J14*税费参数!$B$12/(I14*10000) -> 0.024210526 | M14: =I14*10000*SUM(税费参数!$B$9:$B$10)/税费参数!$B$11 -> 178.125
A15: 华西 | B15: 傲仕门 | C15: 40–60㎡ | D15: 1室1厅 | E15: 106123379786.0 | F15: CD2201683724582518784 | G15: 59.44 | H15: 59.44 | I15: 95 | J15: 2700 | K15: =(J15-M15)*税费参数!$B$12/(I15*10000*(1+SUM(税费参数!$B$6:$B$8))) -> 0.025710463 | L15: =J15*税费参数!$B$12/(I15*10000) -> 0.028421053 | M15: =I15*10000*SUM(税费参数!$B$9:$B$10)/税费参数!$B$11 -> 178.125
A16: 华西 | B16: 傲仕门 | C16: 40–60㎡ | D16: 1室1厅 | E16: 106123379786.0 | F16: CD2214344428011651072 | G16: 59.44 | H16: 57.05 | I16: 95 | J16: 2300 | K16: =(J16-M16)*税费参数!$B$12/(I16*10000*(1+SUM(税费参数!$B$6:$B$8))) -> 0.021632471 | L16: =J16*税费参数!$B$12/(I16*10000) -> 0.024210526 | M16: =I16*10000*SUM(税费参数!$B$9:$B$10)/税费参数!$B$11 -> 178.125
A17: 华西 | B17: 凯蒂阳光 | C17: 40–60㎡ | D17: 1室1厅 | E17: 106123405462.0 | F17: CD2218601000455897088 | G17: 51.94 | H17: 48.56 | I17: 98 | J17: 2600 | K17: =(J17-M17)*税费参数!$B$12/(I17*10000*(1+SUM(税费参数!$B$6:$B$8))) -> 0.023879528 | L17: =J17*税费参数!$B$12/(I17*10000) -> 0.026530612 | M17: =I17*10000*SUM(税费参数!$B$9:$B$10)/税费参数!$B$11 -> 183.75
A18: 华西 | B18: 凯蒂阳光 | C18: 40–60㎡ | D18: 1室1厅 | E18: 106123405462.0 | F18: CD2197054279691272192 | G18: 51.94 | H18: 48.56 | I18: 98 | J18: 2800 | K18: =(J18-M18)*税费参数!$B$12/(I18*10000*(1+SUM(税费参数!$B$6:$B$8))) -> 0.025856105 | L18: =J18*税费参数!$B$12/(I18*10000) -> 0.028571429 | M18: =I18*10000*SUM(税费参数!$B$9:$B$10)/税费参数!$B$11 -> 183.75
... A2593: 西南财大 | B2593: 金沙时代城 | C2593: 40–60㎡ | D2593: 1室0厅 | E2593: 106126871807.0 | F2593: CD1998980433844371456 | G2593: 46.5 | H2593: 46.5 | I2593: 35 | J2593: 1800 | K2593: =(J2593-M2593)*税费参数!$B$12/(I2593*10000*(1+SUM(税费参数!$B$6:$B$8))) -> 0.047993774 | L2593: =J2593*税费参数!$B$12/(I2593*10000) -> 0.051428571 | M2593: =I2593*10000*SUM(税费参数!$B$9:$B$10)/税费参数!$B$11 -> 65.625
